Traceback (most recent call last):
  File "check_voltdb_cluster.py", line 23, in <module>
    r = requests.get(url)
  File "/usr/local/lib/python2.7/dist-packages/requests/api.py", line 75, in get
    return request('get', url, params=params, **kwargs)
  File "/usr/local/lib/python2.7/dist-packages/requests/api.py", line 60, in request
    return session.request(method=method, url=url, **kwargs)
  File "/usr/local/lib/python2.7/dist-packages/requests/sessions.py", line 524, in request
    resp = self.send(prep, **send_kwargs)
  File "/usr/local/lib/python2.7/dist-packages/requests/sessions.py", line 637, in send
    r = adapter.send(request, **kwargs)
  File "/usr/local/lib/python2.7/dist-packages/requests/adapters.py", line 516, in send
    raise ConnectionError(e, request=request)
requests.exceptions.ConnectionError: HTTPConnectionPool(host='192.168.14.21', port=6013): Max retries exceeded with url: /api/1.0/?Procedure=@SystemInformation&Parameters=[DEPLOYMENT]&admin=false&User=admin&Password=bullet (Caused by NewConnectionError('<urllib3.connection.HTTPConnection object at 0x7fa309bddb90>: Failed to establish a new connection: [Errno 111] Connection refused',))
